Workbook

Sheet Raw Data
A1: Unique ID | B1: Archival Collection | C1: Archival Page (r/v) | D1: PDF Page | E1: Date* | F1: Source Location | G1: Source | H1: Source Title | I1: Target | J1: Target Title | K1: Relationship | L1: Cipher | M1: Topic | N1: Language | O1: Transcription | P1: Rough Translation | Q1: Notes
A2: ID_00001 | B2: ASF, Acquisti e Doni, Fol 142, Ins 8. | D2: 38 | E2: 1624/04/12 | F2: Pisa | G2: della Rena, Horatzio | H2: Beaurocrat: Seg.o dem.to | I2: von Habsburg, Maria Magdalena | J2: Ruler: Arciduchessa d'Austria e Gran Duchessa di Toscana | K2: Beaurocratic | O2: Maria Maddalea Arciduchessa d'Austria Gran Duchessa di Toscana Perche la Lavanda, che secondo l'Instituto nostro facciamo ogni Anno ai Poveri nela settimana Santa proceda con ordine, e maggior Devozione Voliamo che Il Canon__o m__ Paolo Tronci danoi espressa__e deputato, Quando ne detti giorni santi saremo In Pisa e legga ogni Anno per Il mercole di santo la mattina, tredici Donne, allequali laveremo li Piedi, et inoltre sette fanciullette, e sei fanciulli, e tutti siano confessati, e cominicati secondo l'eta' loro, et di haver cio eseguito ne habbino fede del Curato, e di questo il detto canonico ne avvisera' avanti, ed'ogn'altra cosa che bisogni portale effetto, Accio le cose passin con quiete e senza confus[io]ne. Havera' ancora particolar cura, che tali persone da eleggersi siano di buona fama povere vergognose, et originarie propie della citta' di Pisa, escludendo tutte l'altre, et avvertira', che la nostra Intension e', che d'una casa e famiglia della per manno cene sara' stato un suggetto, Il susseguente non vi deva piu essere Accio' dell'elemosina, che si da ne possin participare anco gli altri poveri, Per questo egli deve teneme in diligente Registro, e perche tali elezioni sino fatte con piu considerazione e giustizia, voliamo, et ordiniamo al mede s___ can__o che per questo fine, non deva ricever ne ammetter raccomandarne alcuna, Se ben fosse ben'ri stessi servition, e cortigiani. E quelle povere ancora che egli devra e legger p__nto rescritto particolae sieno con tutto cio visitate, e ritrovate habili, e con tutti i Requisiti, siammettin sub[it]o e quanto che no si escludino assolatamente che questa e' la nostra Volonta'. Dato In Pisa 12 Aprile 1624 | P2: Maria Maddalena, Archduchess of Austria, Grand Duchess of Tuscany So that the washing, which according to our Institute we perform each year for the Poor during Holy Week, may proceed with order and greater devotion, We wish Canon Paolo Tronci to give us express and delegated authority. When we are in Pisa on the said holy days and read every year on Holy Wednesday morning, thirteen women, whose feet we will wash, as well as seven girls and six boys, and all are to be confessed and sent according to their ages, and that they have performed this they are to have proof of this from the curate, and the said canon will advise us of this in advance, and anything else that needs to be done, so that matters may pass peacefully and without confusion. He will also take particular care that the people to be elected are of good reputation, poor, shameful, and native to the city of Pisa, excluding all others, and he will note that our intention is that if a subject of a house and family of the same household has been chosen, the next one must no longer be there. In order for the alms to be given, and for other poor people to be able to participate, he must keep a diligent register. And so that such elections are made with greater consideration and justice, we want and order the same person that for this purpose, he must not accept or admit any recommendation, even if they are from the same service and courtiers. And let those poor people, too, whom he will have to read and write in a particular way, be examined with all this, and found to be fit for purpose, and with all the requirements, be admitted immediately, and so long as they are not absolutely excluded, that this is our will. Dated in Pisa, April 12, 1624 | Q2: Una lettera in data di Pisa 12 Aprile 1624 - molte altre lettere e carte riguardarti il g____co del Ponte a Pisa con due ___ della medesime
A3: ID_00002 | B3: ASF, Acquisti e Doni, Fol 142, Ins 8. | D3: 40 | E3: 1623/02/19 | F3: Pisa | G3: della Rena, Horatzio | H3: Beaurocrat: Seg.o dem.to | I3: von Habsburg, Maria Magdalena | J3: Ruler: Arciduchessa d'Austria e Gran Duchessa di Toscana | K3: Beaurocratic | O3: Havendo la Serenissima Arciduchessa Granduchessa veduto con quanto affetto il Cavaliere Giovanbatista santa Proveditore dell'Arsanale protega il gioco del Ponte, Come persona conisciuta da S.A. molto a proposito in comandare alle quadre, lo deputa percio generale di tutta la gente da combattere Pero' non manche di far subito chiamare i detti Capitani di squadre, accio che essi sappinoda noi la nostra volonta' perche ciascuno virenda quella obbedienza che si deve come capo di tutti dalla quale ne procedono i buoni ordini, et la speranza delle Vittorie. Per queso il med.o generale non manche di ordinare i tutti che si mettino allord__e concordemente a fine che ___ si pronto perdar saggio di se med[esimo], et far prova del lor valore del quale SA si promette. | Q3: I think there is either a real or a make-believe/festival battle that Maria Maddalena is coordinating in the spring of 1623..? that's the sense I get from the 2 letters I transcribed and from skimming the documents from there to here; Ok apparently Gioco del Ponte is an annual Pisan festival that still goes on today. See the italian wikipedia page for an overview: https://it.wikipedia.org/wiki/Gioco_del_Ponte
A4: ID_00003 | B4: ASF, Acquisti e Doni, Fol 242, Ins 3. | D4: 5 | E4: 1609/08/22 | F4: Firenze/Fiorenza | G4: von Habsburg, Maria Magdalena | H4: Ruler: Arciduchessa d'Austria e Gran Duchessa di Toscana | I4: d'Elci, Orso | J4: Ambassador: Conte e Ambassadore | K4: Beaurocratic | O4: Ill.re Ambasc.re N.ro dilett.mo Noi scriviamo con l'aggiunta ha alla Maesta' della Regina in raccomandazione d'una lite che ha' in Napoli il Duca di Gravina, come potrete vedere dall'includo memoriale, et per che in essa ha interesse il signr Don Virginio Orsini Duca di Bracciano, per esser quel di Gravina suo parente, vogliamo che presentiate voi stesso la lettera a' S. M.ta quando pero ella si trovi in Madrid; et che le dimostriate anche in vote che questo negotzio mi e' particolarm.te a' cuore, et che pero' la supplichiate efficaccissimamente a' far dare in Napoli quelli ordini, di che l'ho' supplicata, per la buona et favorevole spedizione di quella lite per giustizia; et che procuriate ancora di far dare le lettere a voi, accio' che possiate inviale al medesimo G.D. Virginio, rimettendoci a' quel piu, che' S. Ecc.za medesima vi fara' intendere sopra questo negozio. Habbiamo mandato anche a S. M.ta un memoriale simile, pero' non ci occorre soggiugnervi altro il S.re Iddio vi conservi et contenti. | P4: Dearest Ambassador, We write with the addition to the Queen's Majesty in recommendation of a lawsuit that the Duke of Gravina is having in Naples, as you will be able to see from the enclosed memorial, and since Don Virginio Orsini, Duke of Bracciano, is interested in it, since the Duke of Gravina is her relative, we want you to present the letter to Her Majesty yourself when she is in Madrid; and to also show her in person that this matter is particularly close to my heart, and therefore to beg her most effectively to have the orders given in Naples, for which I have begged, for the good and favorable resolution of that lawsuit for justice; and that you also try to have the letters given to you, so that you can send them to the same G.D. Virginio, referring to what His Excellency Himself will tell you about this matter. We have also sent a similar memorandum to His Majesty, but we need not add anything else. May God keep you safe and happy.
A5: ID_00004 | B5: ASF, Acquisti e Doni, Fol 242, Ins 3. | D5: 6 | E5: 1609/10/13 | F5: Firenze/Fiorenza | G5: von Habsburg, Maria Magdalena | H5: Ruler: Arciduchessa d'Austria e Gran Duchessa di Toscana | I5: d'Elci, Orso | J5: Ambassador: Conte e Ambassadore | K5: Beaurocratic | O5: Il G. Don Virg:Orsino desidera, che la ser_ma sig_ra Arciduchessa gli faccia grazia di due lettere, l'una alla Maesta' della Regina di Spagna, et l'altra al Conte Orso d'Elci Ambasc__re di S. Alt.a in quella Corte, accio__ venga ordinato al Vice Re di Napoli in grazia dell'Alt.a Sua, che sia spedita con presta, et favorevole giustizia la Causa del Duca di Gravina per la pretensione, che ha' di dover succedere nello stato di Bisignano per la morte di Donna Giulia Orsina sua zia, il cui possesso gli viene ritardato per imputazione suscitategli contra de Don Iberio(?) Caraffa marito di d__a Sig__ra nello sparger voce, che ella sia morta di veleno per opera del Duca, beche apparischino del tutto vane dall'esser ella morta d'hidropisia benis__ conosciuta da' medici; oltre al dover essere alieni simili sospetti dalla persona del sud__ Duca, che e' tanto congiunto di sangue col G. Don Virginio, che egli ricevera' questo honore dalla benignita di S. Alt.a per fatto a' se medesimo(?) | P5: The Most Reverend Don Virg: Orsino wishes that the Most Serene Lady Archduchess grant him two letters, one to Her Majesty the Queen of Spain, and the other to Count Orso d'Elci, Ambassador of Her Highness to that Court, so that the Viceroy of Naples may be ordered, in thanks to Her Highness, to dispatch with prompt and favourable justice the Case of the Duke of Gravina for the claim he has to succeed to the state of Bisignano due to the death of Donna Giulia Orsina, his aunt, the possession of which is being delayed by accusations raised against him by Don Iberio(?) Caraffa, the Lady's husband, by spreading rumours that she died of poison at the hands of the Duke, although these rumours appear completely vain since she died of dropsy, which was well known to the doctors; in addition to the fact that such suspicions must be alien to the person of the southern Duke, who is so closely related by blood to the G. Don Virginio, that he will receive this honor from the benevolence of His Highness as a deed to himself(?)
A6: ID_00005 | B6: ASF, Acquisti e Doni, Fol 242, Ins 3. | D6: 8 | E6: 1609/08/22 | F6: Firenze/Fiorenza | G6: von Habsburg, Maria Magdalena | H6: Ruler: Arciduchessa d'Austria e Gran Duchessa di Toscana | I6: d'Elci, Orso | J6: Ambassador: Conte e Ambassadore | K6: Beaurocratic | O6: Ill__re sig__re Ambas__ N__ro dilett__mo. Oltre alla informazione che habbiamo delle vostre nobili et virtuose qualita', si fanno anche talm__te, sentire gl'effetti del buono et accetto servizio che tuttavia fate in cotesta carica, che Noi vi teniamo in quello honorato concetto che si deve al merito vostro, et vi testifichiamo d'haver molto particolarmente aggradito l'ossequente affetto di devozione, che ci havete mostrato con la v[ost]ra lettera, presentataci da mons__re Arcivescovo di Pisa nel suo ritorno. In tanto col servici costa' harete occasione di guadagnare ogni giorno piu' la benevolenza et grazia n[ost]ra; massima__te se ci darete spesso nuove della Maesta' della Regina et procurerete per via del P__re Riccardo suo Confessore, et di altri, et il s_re Iddio conservi | P6: Dearest Ambassador, In addition to the information we have of your noble and virtuous qualities, the effects of the good and acceptable service you are still performing in this office are also so felt that We hold you in that honorable opinion that is due to your merit, and We testify to you that We have particularly appreciated the obsequious affection and devotion that you have shown us with your letter, presented to us by the Archbishop of Pisa on his return. In the meantime, with your services you will have the opportunity to gain our benevolence and grace more and more every day; especially if you will give us frequent news of the Queen's Majesty and will try through Father Riccardo, her Confessor, and others, and may God preserve us. | Q6: he is explicitly tasked with getting information about the Queen THROUGH the confessor (and others). That's what happened during Cosimo's marriage negotiations but I thought it was super weird and shady... is this actually normal and chill, or is getting info from the confessor akin to trading in secrets or espionage? Maybe it isn't since this is MM getting updates on her own sister, who I assume she could just sort of write to whenever she wanted
A7: ID_00006 | B7: ASF, Acquisti e Doni, Fol 242, Ins 3. | D7: 11 | E7: 1610/09/02 | F7: Firenze/Fiorenza | G7: von Habsburg, Maria Magdalena | H7: Ruler: Arciduchessa d'Austria e Gran Duchessa di Toscana | I7: d'Elci, Orso | J7: Ambassador: Conte e Ambassadore | K7: Beaurocratic | O7: Ill__re Ambas__re ___ dilett__mo. Essendoci stato rappresentato da voi il contento che lor Maesta' Cattoliche hanno sentito del Nostro felice parto era ben dovesse che havesse anco luogo la vostra congratulatione particolare, la quale, sapendo Noi esser proceduta da vero devotissimo affetto habbiamo maggiormente aggradita. Vene facciamo fede con questa lora ma piu' velo ratificheremo con le opere ogni volta che havremo occasione d'impiegarci per vostro benefizio et honore, et dal s___re Iddio vi desideriamo prosperita'. | P7: Dearest Ambassador, Since you have expressed to us the joy that Their Catholic Majesties have felt about Our happy birth, it was fitting that your special congratulations should also take place, which, knowing that We have proceeded from truly devout affection, We have greatly appreciated. We bear witness to this with this hour, but we will ratify it more fully with our actions every time we have the opportunity to work for your benefit and honor, and from the Lord God we wish you prosperity. | Q7: Google Translate is translating "parto" to "birth," and I double checked with WordReference that "parto" does in fact mean "birth, childbirth, delivery."
A8: ID_00007 | B8: ASF, Acquisti e Doni, Fol 242, Ins 3. | D8: 13 | E8: 1610/10/09 | F8: Firenze/Fiorenza | G8: von Habsburg, Maria Magdalena | H8: Ruler: Arciduchessa d'Austria e Gran Duchessa di Toscana | I8: d'Elci, Orso | J8: Ambassador: Conte e Ambassadore | K8: Beaurocratic | O8: (to the Ambassador) Noi non havremmo il maggior gusto che di poter gratificare et servire la s__ra Contessa al'Altamira, la quale sappiamo molto bene che e' una s__ra di straordinario merito et di grandissimo valore, si che non ci moveremmo meno per il propio rispetto di lei, che per sapere quanto ella sia grata alla M__ta della Regina. Havendo Noi dunque sentito la richiesta che havete fatto per parte sua di raccomandare in Roma la spedizione del Diaconato di San Jac__o (Jacopo?) gia' proveduto nella persona d'un suo figlio, ne habbiamo scritto con ogni piu' efficace caldezza al s__re Cardinale dal Monte accio che informatosi dello stato di quel negotio, impieghi tutto il favore et l'autorita' sua difficulta' di tal natura che lo ritenghino indietro procuri di scoprirle, a' fine che dandosene avviso costa __ possa pensare a i rimedii di superarle. In somma, se harete occasione di vedere la d__ s__ra Contessa,, oltre al salutarla caram__te per parte nostra assicuratela pure che se bisognera' fare in Roma piu' d'una replica per tener sollecitato il negozio Noi lo faremo spontaneam__te et con la medesima affetione come su fusse cosa di Nostro proprio interesse come anco ci impiegheremo sempre volentierissimo in ogn'altra sua occorrenza. Dateci nuova con ogni Corriero della buona salute di lor Maesta' et de Principi et Principesse lor figliuoli; et il signore Iddio vi contenti. | P8: (to the Ambassador) We would have no greater pleasure than to be able to gratify and serve the Countess of Altamira, whom we know very well to be a lady of extraordinary merit and great value, so much so that we would be moved no less by our own respect for her than by knowing how grateful she is to Her Majesty the Queen. Therefore, having heard the request you made on her behalf to recommend to Rome the despatch of the Diaconate of San Jacopo (Jacopo?), already provided for in the person of one of her sons, we have written with the utmost fervor to Cardinal Dal Monte so that, having learned of the status of that matter, he may employ all his favor and authority to resolve any difficulties of a nature that may hold him back, so that, upon receiving notice, he may consider remedies to overcome them. In short, if you have the opportunity to see the Countess, in addition to greeting her kindly on our behalf, assure her that if it is necessary to make more than one visit to Rome to keep the business moving, we will do so spontaneously and with the same affection as if it were a matter of our own interest, just as we will always gladly contribute to any other need she may have. Please keep us informed by every courier of the good health of Their Majesties and of the Princes and Princesses, their children; and may the Lord God please you.
A9: ID_00008 | B9: ASF, Acquisti e Doni, Fol 242, Ins 3. | D9: 15 | E9: 1610/12/01 | F9: Firenze/Fiorenza | G9: von Habsburg, Maria Magdalena | H9: Ruler: Arciduchessa d'Austria e Gran Duchessa di Toscana | I9: d'Elci, Orso | J9: Ambassador: Conte e Ambassadore | K9: Beaurocratic | O9: (to the ambassador) Noi scriviamo alla M__ta della Regina in raccomandazione d'un desiderio del Marchese Gio:bata dal Monte (Cardinal del Monte or relative?) del tenore che vedrete dalla copia e vogliamo che presentiate voi stesso la lora accompagnandola in voce con quelle piu' efficaci parole che vi sovverranno, massimamente in testificatione del merito di questi sig__re molto ben conosciuti da voi, accio che con tanto maggior caldezza la M__ta sua habbia da favorire il negozio, il quale preme a' Noi grandem__te per le ragioni che habbiamo allegate nella detta letterea. E doppo che havrete fatto l'offitio con S. Mta siatene diligente promotore e sollecitatore appresso di tutti quelli che ci havranno da intervenire come se haveste da affaticarvi per Nostro particolare interesse, che tale stimiamo questo; e Dio vi conservi | P9: (To the ambassador) We write to the Queen's Majesty recommending a request from Marquis Giobata dal Monte (Cardinal del Monte or relative?) of the nature you will see in the copy. We ask you to present it yourself, accompanying it verbally with the most effective words you can think of, especially in testimony to the merit of these gentlemen, who are very well known to you, so that her Majesty may all the more fervently support the matter, which is of great importance to Us for the reasons we have set forth in the aforementioned letter. And after you have fulfilled your duties with Her Majesty, be a diligent promoter and solicitor of it to all those who will have to intervene, as if you were working for Our particular interest, for such We consider this to be the case; and God bless you.
A10: ID_00009 | B10: ASF, Acquisti e Doni, Fol 242, Ins 3. | D10: 17 | E10: 1610/02/10 | F10: Firenze/Fiorenza | G10: von Habsburg, Maria Magdalena | H10: Ruler: Arciduchessa d'Austria e Gran Duchessa di Toscana | I10: d'Elci, Orso | J10: Ambassador: Conte e Ambassadore | K10: Beaurocratic | O10: (to the ambassador) Noi scrivemmo gia' alla Maesta' della Regina, supplicandola a' favorire il sr felice di Gennaro, gentilhuomo Napolitano, per un luogo di Presidente, vacato per la morte del s__re scipione de curtis. Et per che il medesimo carico era anche chiesto da un altro Curtis, la qual famiglia e' stata sempre affezzionata di questa Casa, et il Gran Duca stesso scrisse alla Maesta' del Re in sua raccomandatione. Noi non ne facemmo instanza, se non in caso che il Curtis non ne fusse compiaciuto. Ora intendiamo che egli ne debbe essere escluso, et pero' se voi vi chiarirete che questo sia vero, vogliamo che opportunamente ricordiate, o' facciate ricordare alla Regina la Nostra richiesta in benefizio del Gennari, con assicurarla che questa gratia sara' ricevuta da Noi come propria; et il signore Iddio vi contenti.
A11: ID_00010 | B11: ASF, Acquisti e Doni, Fol 242, Ins 3. | D11: 20 | E11: 1611/06/08 | F11: Firenze/Fiorenza | G11: von Habsburg, Maria Magdalena | H11: Ruler: Arciduchessa d'Austria e Gran Duchessa di Toscana | I11: d'Elci, Orso | J11: Ambassador: Conte e Ambassadore | K11: Beaurocratic | M11: Recommendation | O11: E capitato qua' un giovane Tedesco, chiamato Gio: Ridolfo Vitzman suddito del serenissimo Arciduca Leopoldo nostro fratello nel vescovado d'Argentina, e ci ha' detto esser fuora della patria sua et anco privo de suoi beni per haver voluto lasciar heresie e ridursi a' vivere nella fede Cattolica; et essendosi risoluto di venire in Spagna per procurar qualche avviamento da poter vivere, ci haveva richiesto che Noi scrivessimo in sua raccomand__ne alla M.ta della Regina ma ci e' parso che basti di scrivere a' voi accio che sentiate le pretensioni di quest'huomo, e de qui vi giadichiate fino a qual segno convenga che ne parliate alla M.ta sua. Ci sara' ben caro che se vediete congiuntura buona da poterlo aiutare, o' in un modo o' in un altro voi lo facciate; e Dio vi conservi. | P11: A young German named Gio. Ridolfo Vitzman, a subject of the Most Serene Archduke Leopold, our brother in the bishopric of Argentina, arrived here. He told us that he was exiled from his homeland and deprived of his property because he had chosen to abandon heresies and return to living in the Catholic faith. Having resolved to come to Spain to find some means of support, he had asked us to write to recommend him to Her Majesty the Queen, but it seemed to us sufficient to write to you so that you might hear the man's claims and from there decide to what extent you should speak to Her Majesty about him. We would be very pleased if, if you see a good opportunity to help him, you would do so in one way or another; and God bless you. | Q11: Man claims to have been ousted from his home in Leopold V's Austria for being Catholic (because of the Protestant tensions there that led to the 30 years war etc), and has arrived in Florence but wants to go to Spain
A12: ID_00011 | B12: ASF, Acquisti e Doni, Fol 242, Ins 3. | D12: 22 | E12: 1611/07/22 | F12: Firenze/Fiorenza | G12: von Habsburg, Maria Magdalena | H12: Ruler: Arciduchessa d'Austria e Gran Duchessa di Toscana | I12: d'Elci, Orso | J12: Ambassador: Conte e Ambassadore | K12: Beaurocratic | O12: Ill. signore Cont'Orso Ambas.re nostro Dilett__mo Per. Il Leoni Corr__ Regio che passe a cote stavolta vi mand__mo in Rimvolto (?) ben ammagliato, dentro al quale a una vesta la quale per via de la s__ Contessa di Lemos, o, In quellla maniera, che piu parra' alla vostra prudenzia, Voliamo che presentiate in nostro nome alla M__ta della Regina di franc__a nostra nipote, et accompagniate questo Regalo, con quelle parole di complimento, che piu sonnerranno alla vostra discrezione, et che noi ci promettiamo dalla vostra destrezza, presentandola piu tosto come veste da viaggio, accio' tanto maggiorante venga scusato la tenuita' del Don__ et Honesto molto ardire. Dandoci poi __uviso che cosi l'haviate eseguisto, et Il s__ vi prosperi | P12: Illustrious Lord Count Orso, Our Most Beloved Ambassador, Per. Il Leoni, Royal Courier, who is passing by this time, we are sending you in a well-meshed wrapper (?), inside which is a dress which, by way of the Countess of Lemos, or, in whatever manner seems most to your prudence, We wish you to present in our name to the Lady of the Queen of France, our niece, and accompany this Gift with those words of compliment which will most please your discretion, and which we promise ourselves by your dexterity, presenting it rather as a travelling dress, so that the smallness of the Gift may be all the more excused and Honestly very bold. Then giving us approval that you have carried it out in this way, and may He prosper you.
A13: ID_00012 | B13: ASF, Acquisti e Doni, Fol 242, Ins 3. | D13: 24 | E13: 1611/09/12 | F13: Firenze/Fiorenza | G13: von Habsburg, Maria Magdalena | H13: Ruler: Arciduchessa d'Austria e Gran Duchessa di Toscana | I13: d'Elci, Orso | J13: Ambassador: Conte e Ambassadore | K13: Beaurocratic | M13: Childbirth | O13: Ill__ri Ambas__re Nostro dilett__mo. Essendoci ormai noto il devotiss__o affetto vostro verso di noi, stimavamo superflua la testifiazione della vostra allegrezza per l'ultimo felice parto che Dio ci ha concedato; non dimeno c'e' stata gratissima l'espressione fatta cene da voi per lettera; e vi confermiamo quella volonta' che altre volte havete potuto conoscere in Noi verso ogni vostro benefizio et onore, anzi con l'augmento che meritano le vostre virtu'. et il corso della buona e da noi molto agradita servitu' vostra in cotesta carica; e dal sig__re Iddio vi desideriamo ogni maggior bene | P13: Our beloved Illustrious Ambassadors, Since your most devoted affection for us is now known to us, we considered it superfluous to express your joy at the latest happy birth that God has granted us; nevertheless, the expression you expressed in your letter was most pleasing to us; and we confirm to you the desire that you have on other occasions been able to recognize in Us for all your benefits and honors, indeed for the increase that your virtues deserve, and the progress of your good and very welcome service in this office; and from the Lord God we wish you every greater good. | Q13: the ambassador congratulated MM on the birth of GiovanCarlo de' Medici (July 24 1611) and she says thanks
A14: ID_00013 | B14: ASF, Acquisti e Doni, Fol 242, Ins 3. | D14: 26 | E14: 1615/10/02 | F14: Cafaggiuolo | G14: von Habsburg, Maria Magdalena | H14: Ruler: Arciduchessa d'Austria e Gran Duchessa di Toscana | I14: d'Elci, Orso | J14: Ambassador: Conte e Ambassadore | K14: Beaurocratic | M14: Recommendation | O14: Dovera' esservi presentata questa dal signore Fran___ Mareri(?) Gentilhuomo Romano, il quale transferendosi costa' per alcuni suoi affari, riconera' all'opera, et aiuto vostro, per poter'essere tanto piu' facile, et favorevolmente spedito; et Noi, che desideriamo grandem__ di giovarli, per rispetto di chi cen'ha' ricerco, haveremo cariss__ oltre modo, che secondo le richieste, che di mano in mano egli vene fara' voi parliate a' favor suo in nome nostro, et a' s. m__ta, et al signore Duca di Lerma, et a' chiun___ altri bisogni; siche fatelo con ogni prontezza, et efficacia, et il signore Iddio vi conservi, et contenti | P14: This must be presented to you by Mr. Francesco Mareri(?), a Roman gentleman, who, having moved there for some business of his, will turn to your work and help, so that things can be much easier and more favorably expedited; and We, who greatly desire to help him, out of respect for those who have requested it, will be very kind, in particular, that according to the requests that he will make from time to time, you speak on his behalf in our name, and to his Majesty, and to the Lord Duke of Lerma, and to anyone else in need; so do it with all promptness and effectiveness, and may the Lord God preserve you and be happy. | Q14: basically a rec letter
A15: ID_00014 | B15: ASF, Acquisti e Doni, Fol 242, Ins 3. | D15: 28 | E15: 1615/10/22 | F15: Firenze/Fiorenza | G15: von Habsburg, Maria Magdalena | H15: Ruler: Arciduchessa d'Austria e Gran Duchessa di Toscana | I15: d'Elci, Orso | J15: Ambassador: Conte e Ambassadore | K15: Beaurocratic | M15: Intelligence | O15: Il Pre__ Pedro Garzes non e' ancora comparso qua', ma' Noi habbiamo in ogni modo ricevuto la lettera, che voi gli deste per Noi, et poi vedremo voltentieri ancor lui, quando egli passera' di qua'. Quelle Cifere lasciatevi in mano da lui, hacete fatto bene a' non mandarle, et le brucerete, et il signore Iddio vi conservi, et contenti | P15: you did well not to send the ciphers he gave you and (future tense, as if he hasn't done so yet and this is an instruction) burn them | Q15: a priest gave Orso d'Elci secret ciphers! MM says good job not forwarding them, burn them!
A16: ID_00015 | B16: ASF, Acquisti e Doni, Fol 242, Ins 3. | D16: 30 | E16: 1611/11/06 | F16: Siena | G16: von Habsburg, Maria Magdalena | H16: Ruler: Arciduchessa d'Austria e Gran Duchessa di Toscana | I16: d'Elci, Orso | J16: Ambassador: Conte e Ambassadore | K16: Beaurocratic | M16: Death | O16: Sappiamo che havreste voluto far con noi qualsivoglia altro offizio, che darci nuova cosi' dolorosa, come e' stata quella della morte della morte della M__ta' della Regina, Nostra amatissima sorella. ci e' stata non dimeno gratissima la condoglienza che n'havete fatta con esso noi, sapendo che e' proceduta dall'intimo del vostro cuore; poiche oltre al devotissimo affetto vostro verso il servizio di questa Casa ci e' nota la part_re osservanza che portavate a' quella benedetta anima, et la confidenza che ella haveva nella persona vostra. Questi rispetti accresceranno in Noi ogni di piu' l'inclinazione et la volonta' che portiamo al merito della vostra buona et accetta servita; et vela confermeremo anche con l'opere; e Dio vi contenti | P16: We know that you would have liked to do us any other service than to give us news as painful as that of the death of the Majesty of the Queen, Our most beloved sister. Nevertheless, the condolence you have expressed to us has been most grateful, knowing that it came from the depths of your heart; for, in addition to your most devoted affection for the service of this House, we are aware of the special respect you had for that blessed soul, and the confidence she had in you. These respects will further increase in Us the inclination and the will we have to merit your good and acceptable service; and we will also confirm it with our works; and may God please you. | Q16: Ambassador brought MM the news of her sister's death (Queen of Spain); Margaret is only 3 years older than MM and she died at age 26
A17: ID_00016 | B17: ASF, Acquisti e Doni, Fol 242, Ins 3. | D17: 35 | E17: 1612/06/19 | F17: Firenze/Fiorenza | G17: von Habsburg, Maria Magdalena | H17: Ruler: Arciduchessa d'Austria e Gran Duchessa di Toscana | I17: d'Elci, Orso | J17: Ambassador: Conte e Ambassadore | K17: Beaurocratic | M17: Death | O17: Ci e' dispiaciuta grandem__te la morte del P~re Riccardo Haller, gia' confessore della Regina Nostra sorella, perche lo conoscevamo per un buono e savio religioso, e percio' gli portavamo affezzione piu' che ordinaria. Habbiamo sentito la diligenza che havevate fatto accio' si mettessero da banda le scritture che egli teneva in lingua Alemanna, per farle abbruciare, ma se elle sono ancora in essere, desidereremmo che voi procuraste di farvele consegnare per mandarle qua' in Nostra mano, poiche una parte di esse sono uscite da Noi per farlo mostrare alla Maesta' della Regina, e quando bisogni dirne una parola al signore Duca di Lerma, fatelo per parte Nostra; e Dio vi conservi | P17: We were greatly saddened by the death of Father Richard Haller, former confessor of Our Sister Queen, because we knew him to be a good and wise religious man, and therefore we had a more than ordinary affection for him. We have heard of the diligence you have made to have the writings he kept in the German language put aside for burning, but if they are still in existence, we would like you to try to have them delivered to you so that we can send them here into Our hands, since some of them have been left by Us to be shown to the Queen's Majesty, and when it is necessary to say a word about them to the Lord Duke of Lerma, do so on Our behalf; and God save you. | Q17: Queen of Spain's confessor (is Riccardo Haller the same confessor she had while Ferdinando I was arranging Cosimo II's marriage who leaked information?); ok, really interesting about the Queen's confessor having writings from her in German that MM wants burned; I'm very interested in secrecy in these letters and I wonder if it warrants a chapter in the project... something called "Family Secrets" that analyzes the use of ciphers in family correspondence/important gov issues like marriage negotiations
A18: ID_00017 | B18: ASF, Acquisti e Doni, Fol 242, Ins 3. | D18: 37 | E18: 1612/07/10 | F18: Firenze/Fiorenza | G18: von Habsburg, Maria Magdalena | H18: Ruler: Arciduchessa d'Austria e Gran Duchessa di Toscana | I18: d'Elci, Orso | J18: Ambassador: Conte e Ambassadore | K18: Beaurocratic | M18: Recommendation | O18: La famiglia de Malvezzi di Bologna, come voi sapete, e' tanto conosciuta in Europa, che anco in cotesta corte crediamo esserne particolar notizia. E perche tutti hanno fatto sempre aperta professione d'esser serv__ri affezzionati e parziali di questa Casa, non habbiamo voluto mancare di compiacere il Signore Jacopo Malvezzi con una nostra raccomandazione, intoerno al suggetto contenuto nell'incluso suo memoriale. Non c'e' parso gia' conveniente di scrivere al Re medesimo, per non dargli moltestia con Nostre lettere in simili materie; ma commettiamo bene a' voi, che facciate offizio per il detto signore Jacopo, in tutto quello che conoscerete potergli giovare, parlandone non solamente a' i ministri principali ma anche a' S. M.ta medesima, se lo giudicherete opportuno, et che la qualita' della pretensioni vene diano animo; il che rimettiamo alla prudenza vostra, e Dio vi contenti | P18: The Malvezzi family of Bologna, as you know, is so well known in Europe that we believe it is well-known even in this court. And since they have always openly professed to be affectionate and sympathetic servants of this House, we did not want to fail to please Lord Jacopo Malvezzi with our recommendation regarding the subject contained in his enclosed memoir. We have not yet deemed it appropriate to write to the King himself, so as not to inconvenience him with our letters on similar matters; but we urge you to make an effort on behalf of the said Lord Jacopo in everything you know that can be of help to him, speaking about it not only to the principal ministers but also to His Majesty himself, if you deem it appropriate, and that the nature of the claims encourages you; which we leave to your prudence, and may God be pleased with you. | Q18: recommendation of Jacopo Malvezzi of Bologna
A19: ID_00018 | B19: ASF, Acquisti e Doni, Fol 242, Ins 3. | D19: 39 | E19: 1612/07/28 | F19: Firenze/Fiorenza | G19: von Habsburg, Maria Magdalena | H19: Ruler: Arciduchessa d'Austria e Gran Duchessa di Toscana | I19: d'Elci, Orso | J19: Ambassador: Conte e Ambassadore | K19: Beaurocratic | M19: Recommendation | O19: Volentieri sempre ci adoperemo per voi et per tutti i vostri parenti, et amici raccomandatici, come faremmo ancora al presente nella domanda del Dottor Jantoni, se non credessimo, che gia S.A. havessi determinato nell'animo suo il suggetto per questa Rutta; pero' non stimia__ poterne succedere altro. In altre occasioni saremo sempre pronte ad aiutarlo, et farli conoscere il conto, che facciamo della vostra intercessione, et restando con la solita buona volonta verso di voi preghiamo il Re vi prosperi | P19: We will always gladly do our best for you and for all your relatives and friends recommended to us, as we would do at present in response to Dr. Jantoni's request, if we did not believe that His Majesty had already determined in his mind the subject for this Rutta (role..?); however, we do not believe anything else could happen. On other occasions, we will always be ready to help him and let him know the value we have of your intercession, and remaining with the usual good will towards you, we pray that the King may prosper you. | Q19: Polite negative response to a recommendation
A20: ID_00019 | B20: ASF, Acquisti e Doni, Fol 242, Ins 3. | D20: 41 | E20: 1612/08/07 | F20: Firenze/Fiorenza | G20: von Habsburg, Maria Magdalena | H20: Ruler: Arciduchessa d'Austria e Gran Duchessa di Toscana | I20: d'Elci, Orso | J20: Ambassador: Conte e Ambassadore | K20: Beaurocratic | O20: Il contento che havete mostrato del nostro ultimo parto con salute e' stato conforme al vostro solito devotissimo affetto verso di Noi, e pero' habbiamo aggradito l'offizio quanto conveniva. Gia' sapevamo quanto era grata alla M.ta della Regina Nostra sorella che sia in Cielo, la servitu' della signora Duchessa di Gandia, e pero' ci e' stato accettissimo il complimento che ella ha' fatto con Noi, et nela ringraziamo con la risposta che sara' con questa; alla quale la presenterete, facendole anche fede in voce di quanto ella si puo' promettere di Noi nelle occorrenze di suo servizio. In proposito delle lettere et scritture che potesse havere il P~re Riccardo Haller (The Queen's confessor who recently passed away), non ci occorre replicar altro, havendo noi fatto tutta la diligenza che si poteva; e Dio vi conservi | P20: The happiness you have shown at our recent and healthy birth was consistent with your usual, most devoted affection toward Us, and therefore We have accepted the service as appropriate. We already knew how grateful the Queen, Our sister in Heaven, was for the service of the Duchess of Gandia, and therefore the compliment she paid Us was most welcome, and We thank her for it with the reply that will be included with this one, to which you will present her, also verbally confirming to her what she can promise of Us in the circumstances of her service. Regarding the letters and writings that Father Richard Haller (the Queen's confessor who recently passed away) may have, We need not reply further, having done all the diligence we could; and God bless you. | Q20: it's not clear what happened to the documents Father Richard Haller had from the Queen... it sounds like MM's two desired outcomes (either burn them or get them to her) may not have happened and she has dropped the issue, but I am not sure; also, another congrats on another birth. This time it must be about Margherita (31 May 1612). Was Margherita named for his sister Queen Margherita of Spain who just passed? That is such an interesting coincidence that her first daughter after the Queen's death is named Margarita, so I wonder if that is the case.
A21: ID_00020 | B21: ASF, Acquisti e Doni, Fol 242, Ins 3. | D21: 44 | E21: 1613/04/13 | F21: Firenze/Fiorenza | G21: von Habsburg, Maria Magdalena | H21: Ruler: Arciduchessa d'Austria e Gran Duchessa di Toscana | I21: d'Elci, Orso | J21: Ambassador: Conte e Ambassadore | K21: Beaurocratic | M21: Recommendation | O21: E' capitato qua ___ [vostro?] Cav__re di Malta Tedesco chiamato fra Gio:David Veiller, il quale raccontro di haver servito S Mta Catt[olic]a in mare con alcuni suoi Vasselli propii sotto la __ia del Conti Scerlei Inglese. Di poi dice esser venuto in discordia con il detto Conte per le cagioni che voi sentirete dall'aggiunto memoriale et egli stesso dovra' informarvi anche muoce, poiche due di voler venir a' cotesta Corte per questa, et altre sua pretensioni, et havendoci richesto(?) li qualche favore, non ci e' parso di poterne mancare, per essere egli di quella nazione, pero' ascoltatelo volentieri, et conoscendo che le sue doma[n]de habbino qualche appare__ra di giustitia, giovare, se bene ci rimettiamo alla prudenza vostra che facciate questo offitio fino a' quel segno che vi parra', et con le debiti coriospetione (?), et il signore Dio vi conservi | P21: A German Knight of Malta called Fra Gio:David Veiller happened to come here, and he said he served the Catholic Church at sea with some of his own vessels under the command of the English Count Scerlei. Then he says he has come into disagreement with the said Count for the reasons that you will hear from the attached memorial and he himself will also have to inform you of this, since two of them want to come to that Court for this and other pretensions of his, and having asked us (?) for some favor, it did not seem to us that we could refuse it, since he is of that nation, therefore listen to him willingly, and knowing that his requests have some appearance of justice, to help, although we leave it to your prudence to carry out this office up to the point that seems to you, and with the due consideration (?), and may the Lord God preserve you | Q21: There are a few occasions where someone asks MM for her aid and intercession and then MM tells Count Orso about it and basically passes the torch to him. So I guess this is her making good on her promises to intercede for those folks.
A22: ID_00021 | B22: ASF, Acquisti e Doni, Fol 242, Ins 3. | D22: 46 | E22: 1613/08/16 | F22: Firenze/Fiorenza | G22: von Habsburg, Maria Magdalena | H22: Ruler: Arciduchessa d'Austria e Gran Duchessa di Toscana | I22: d'Elci, Orso | J22: Ambassador: Conte e Ambassadore | K22: Beaurocratic | O22: Noi facevamo tanta stima della bonta' e del merito del Pre~ Riccardo Haller mentre egli visse che l'havevamo quasi in venerazione onde quando non havessimo altra notizia del Pre Pietro Garzes, ci basterebbe il sapere che egli sia stato compagno d'un si buon Religioso per tenerlo in un ottimo concetto come veram[ente?] lo teniamo. Alli giorni passati ricevemmo una sua lettera, per la quale ci fece un amorevolissimo saluto in nome di cotesti signore Principe e Principesse, offizio da noi sommamente gradito et apprezato. Pero' vogliamo che voi ringraziando per parte Nostra il detto Padre dell'ambasciata fattaci, lo preghiate ancora, che quando egli ne havra' opportuna occasione baci le mani per noi alli detti signori Principi et Principesse. __rendendo loro le nostre salutazioni affettuosissimamente Gli farete anche fede dell'affezzionata volonta' che portiamo a' lui, et che ci impiegheremo sempre volentierei per ogni suo benefizio e contento; e Dio vi conservi | P22: We had such high regard for the goodness and merit of Father Richard Haller while he lived that we almost held him in veneration. Even if we had no further news of Father Peter Garzes, it would be enough for us to know that he was the companion of such a good religious man to hold him in the highest regard, as we truly do. A few days ago we received a letter from him, in which he sent us a most loving greeting on behalf of the Prince and Princess, an office we have great gratitude and appreciation. Therefore, we wish you, while thanking the said Father on our behalf for the message he sent us, to also ask him to kiss the hands of the said Princes and Princesses for us when he has the appropriate opportunity. By returning our most affectionate greetings to them, you will also give proof of the affectionate desire we bear him, and that we will always willingly employ ourselves for his every benefit and happiness; and God keep you | Q22: Pietro Garzes is the SAME GUY who tried to give Count Orso ciphers and MM said to burn them. See PDF page 28.
A23: ID_00022 | B23: ASF, Acquisti e Doni, Fol 242, Ins 3. | D23: 48 | E23: 1613/10/03 | F23: Firenze/Fiorenza | G23: von Habsburg, Maria Magdalena | H23: Ruler: Arciduchessa d'Austria e Gran Duchessa di Toscana | I23: d'Elci, Orso | J23: Ambassador: Conte e Ambassadore | K23: Beaurocratic | O23: Il Duca di Gravina e' parente stretto del signore Don Virginio tanto congiunto con questa Casa quanto noi sapete, pero' mi par d'essere in obbligo di giovare alle cose sue in tutto quello che per me si possa Ci ha' fatto intendere di havere in cotesta corte alcune liti di non piccola importanza, et richiesstoci di favorirlo con nostre lettere. Vogliamo adunque che voi vi adoperiate in aiuto suo, parlandone non oblamente a' i preincipali ministri, et ad ogni altro che bisogni, ma a' S. Mta medesima, sene sareste richiesto dalli Agenti del detto Daca, iquali vi doveranno informare di tutto il negozio cosi(?) vene governereste in quel modo che vi dettera' la solita vostra prudenza, purche il Duca sappia che Noi vi habbiamo raccomandato questi suoi affari con molta caldezza; e Dio vi conservi | P23: The Duke of Gravina is a close relative of the lord Don Virginio, so closely connected with this House as we know, therefore I feel obliged to help him in all that I can. He has made it known to us that he has some disputes of no small importance at this court, and has asked us to assist him with our letters. We therefore want you to take action to help him, speaking about it not obliviously to the principal ministers, and to anyone else who is necessary, but to Her Majesty herself, if you are requested to do so by the agents of the said Duke, who must inform you of the entire affair, so that you will manage it in the way that your usual prudence dictates, provided that the Duke knows that We have recommended these affairs of his to you with great warmth; and God preserve you.
A24: ID_00023 | B24: ASF, Acquisti e Doni, Fol 242, Ins 3. | D24: 50 | E24: 1613/11/15 | F24: Firenze/Fiorenza | G24: von Habsburg, Maria Magdalena | H24: Ruler: Arciduchessa d'Austria e Gran Duchessa di Toscana | I24: d'Elci, Orso | J24: Ambassador: Conte e Ambassadore | K24: Beaurocratic | O24: Voi vedete dall'alligato foglio il merito de' servitti fatti a' coste sta Corona da Conte Marc'Antonio Malvezzi et la ragione ch'egli ha (di o chi?) pretendere la mercede, che chede a' S. Mta, o' d'un titolo di Marchese nel Regno di Napoli per suo aiuto di costa, o' d'una pensione; et perche oltre all'esser Cav. to molto degne, et stimabili qualita' et accett__ ser__ del Gran Duca costro signore et marito, e anche da noi molto amato, sentiremo volentieri, che abbracciando voi la sua Domanda gia' indotta, et assai bene incaminata da un suo Agente, per quanto egli ci affirma, facciati tutto quello, che sia possibile in aiuto del buon'effetto di essa scrivendone noi cosi efficacemente con approvatione, et licenza di S.A.; et Il [signore] Iddio vi conservi, et contento | P24: You see from the attached sheet the merit of the services rendered to this Crown by Count Marc'Antonio Malvezzi and the reason he has for asking for the mercede (compensation, reward?) he asks of His Majesty, either the title of Marquis in the Kingdom of Naples for his help in the cost, or a pension; and because, in addition to being a Knight of very worthy and estimable qualities and accepted servant of the Grand Duke, this lord and husband, and also much loved by us, we will gladly hear that, embracing his Request already induced, and very well directed by one of his Agents, as he affirms to us, you will do everything possible to help the good effect of it by writing to us so effectively with the approval and permission of His Highness; and may [Lord] God preserve you, and be pleased
A25: ID_00024 | B25: ASF, Acquisti e Doni, Fol 242, Ins 3. | D25: 53 | E25: 1614/02/06 | F25: Firenze/Fiorenza | G25: von Habsburg, Maria Magdalena | H25: Ruler: Arciduchessa d'Austria e Gran Duchessa di Toscana | I25: d'Elci, Orso | J25: Ambassador: Conte e Ambassadore | K25: Beaurocratic | O25: Scriviamo al Re Innsp__ [Innspruch?] della sua amorevolissime lettera, e voliamo che con S. Mta medesimo nel presentargliela, et con che vi pare a proposito significhiate Il dispiacer che haviamo havuto della Indisp[ensio]ne de serenissimi suoi figli nostre nipoti, della cui salute ci seriverete spesso premendoci molto, e furete anco sapere, che Madama Madre, et io procureremo, che sieno apparecchiati certi Remedii per levar' i segni del Vaiolo, che son sicure, e provati ne figli ______ Casa Et havremo anco caro, che ci ragguagliate qualche volta delle Cose di cotesta Corte, poiche non vi e' piu ness[un]o che se ne avvisi, et il [signore Iddio] vi prosperi | P25: We write to King Innsp__ [Innspruch?] of his most loving letter, and we want you to convey to His Majesty himself, in presenting it to him, and with what you think is appropriate, the regret we have had for the indispensability of his most serene children, our nipoti, about whose health you will often serve us by pressing us much, and you will also want to know that My Lady Mother (Christine of Lorraine, probably) and I will ensure that certain remedies are prepared to remove the signs of smallpox, which are safe and proven in the sons of the House. And we would also like you to inform us sometimes of the affairs of this Court, since there is no one left who takes notice of them, and may the Lord God prosper you.
A26: ID_00025 | B26: ASF, Acquisti e Doni, Fol 242, Ins 3. | D26: 55 | E26: 1616/04/15 | F26: Firenze/Fiorenza | G26: von Habsburg, Maria Magdalena | H26: Ruler: Arciduchessa d'Austria e Gran Duchessa di Toscana | I26: d'Elci, Orso | J26: Ambassador: Conte e Ambassadore | K26: Beaurocratic | M26: Recommendation | O26: Venendosene a cotesta Corte Ottavio Bernardi Gentilhomo Bolognese per suoi particolar negozii ci ha fatto ricercar di Volerci scrive__re In sua raccomandazione, et haviamo voluto compiacer' chi con ha richiesto, ma pero' con rimettere alla vostra discrezione, e solita prudenza Il farli in quelle occorrense che vi parrandi puro suo serv__o et nostra sodisfaccione. et Il signore vi prosperi | P26: Ottavio Bernardi, a gentleman from Bologna, having come to this Court for his particular business, has asked us to write to us on his recommendation, and we wanted to please those who have requested it, but we leave it to your discretion and usual prudence to do so in those cases where it seems to you to be his pure servant and to our satisfaction. And may the Lord prosper you. | Q26: She does "intercede" on behalf of everyone who asks, but really she just goes "hey this guy asked me for help and I said yes, but he's your problem now, do whatever you want." That's the sort of glib way of looking at it, obviously it is more complicated and speaks to the competence of Count Orso, their relationship, MM's obligations for interceding for basically anyone who asks, etc.
A27: ID_00026 | B27: ASF, Acquisti e Doni, Fol 242, Ins 3. | D27: 57 | E27: 1616/04/20 | F27: Firenze/Fiorenza | G27: von Habsburg, Maria Magdalena | H27: Ruler: Arciduchessa d'Austria e Gran Duchessa di Toscana | I27: d'Elci, Orso | J27: Ambassador: Conte e Ambassadore | K27: Beaurocratic | O27: La vostra lettera de 19 di febbraio cosi prina di ragguagli della buona salute di S. Mta et de i serenissimi sposi, et degli altri Infanti miei nipoti mi e stata grat__ma, et desidero, che andiate continuando di darmene spesso avviso, essendomi per l'osservanza, et affezion, ch'io gli porto, molto a' cuore il saperne nuove. Mi e stata anco oltre modo cara la notizia, che m'havete data di quello, vi ha' conferito il signore duca di Lerma, et della buona correspondenza, che cui ha promesso tener con esso voi per aumentarei la buona gratia di S. Mta, et come haviamo resoluto d'a__ttare le sue Amorevoli offerte, et il vostro consiglio, cosi volgiamo che nel presentargli le accluse gli rendiate gratie in nome nostro, soggiungendoli quelche piu parra' a proposito alla vostra destrezza, e prudenza, nella qual ci rimettiamo, e preghiamo Il signore che vi prosperi | P27: Your letter of February 19th, so full of information about the good health of His Majesty and of the Most Serene spouses, and of the other Infani, my nipoti, was grateful to me, and I desire that you continue to inform me of it often, since, due to the respect and affection that I bear him, I am very keen to hear news. I was also extremely pleased with the news you gave me of what the Lord Duke of Lerma has given you, and of the good correspondence he has promised to maintain with you to increase the good graces of His Majesty, and just as we have resolved to accept his loving offers and your advice, so we desire that in presenting him with the enclosed letters you return thanks in our name, adding whatever seems most appropriate to your dexterity and prudence, in which we rely, and we pray the Lord that you prosper. | Q27: the good health of His Majesty and of the most serene spouses..? This is 1616. Margaret died in 1611 and Phillip never remarried so I'm not sure what this means.
A28: ID_00027 | B28: ASF, Acquisti e Doni, Fol 242, Ins 3. | D28: 62 | E28: 1616/02/08 | F28: Firenze/Fiorenza | G28: von Habsburg, Maria Magdalena | H28: Ruler: Arciduchessa d'Austria e Gran Duchessa di Toscana | I28: d'Elci, Orso | J28: Ambassador: Conte e Ambassadore | K28: Beaurocratic | M28: Recommendation | O28: Sapete che altre volte haviamo scritto costa a favor'del Dottor Pompeo Battaglino, hora essendo vacata in Napoli nella sommaria una Piazza di Presid__te [or maybe Prend__te?] per morte del' Dottor Giulio Minadois, e venendo ricercata di volei di nouvo scriver al' signore Duca d'Uzeda accio' l'impetri haviamo voluto scriver' a voi solamente, e voliamo, che in quel miglior' modo, che giudicherete piu aproposito procuriate che il d__ Duca dacci offitio costa', e col Vice Re di Napoli per questa giusta pretensione del'Battaglino, e non mancate della solita vostra buona diligenza, che ne sentiremo molto piace, e nostro __ig__ vi prosperi | P28: You know that on other occasions we have written here in favor of Doctor Pompeo Battaglino, now that a Presid__te Square [or maybe Prend__te?] has been vacant in Naples due to the death of Doctor Giulio Minadois, and since we are asked to write again to the Lord Duke of Uzeda to obtain it, we wanted to write to you only, and we want you to ensure that the Duke gives us this office in the best way that you deem most appropriate, and with the Viceroy of Naples for this just claim of Battaglino, and do not fail in your usual good diligence, for we will be very pleased with it, and our good fortune to you.
A29: ID_00028 | B29: ASF, Acquisti e Doni, Fol 242, Ins 3. | D29: 64 | E29: 1618/03/15 | F29: Pisa | G29: von Habsburg, Maria Magdalena | H29: Ruler: Arciduchessa d'Austria e Gran Duchessa di Toscana | I29: d'Elci, Orso | J29: Ambassador: Conte e Ambassadore | K29: Beaurocratic | M29: Recommendation | O29: Viene al Capldhnle..? il Pre fra Gregorio da Rassina ministro de m__ oss__ti di Toscana, quale noi vi raccomandiamo, accio lo aiutiate in quelle honeste domande, e pretensioni di esser promosse al Diffinitorato [word crossed out i think], o' guardiano di herusalem/Gerusalem, che egli desidera rimettendocene pero' alla molta prudenza vostra, pregando il Sig__re che vi prosperi | P29: The priest Fra Gregorio da Rassina, minister of the monks of Tuscany, comes to ___, whom we recommend to you, so that you may help him in those honest requests and claims to be promoted to the office of [word crossed out i think], guardian of Jerusalem, which he desires, leaving it however to your great prudence, praying to the Lord that he may prosper you.
A30: ID_00029 | B30: ASF, Acquisti e Doni, Fol 242, Ins 3. | D30: 66 | E30: 1618/03/26 | F30: Firenze/Fiorenza | G30: von Habsburg, Maria Magdalena | H30: Ruler: Arciduchessa d'Austria e Gran Duchessa di Toscana | I30: d'Elci, Orso | J30: Ambassador: Conte e Ambassadore | K30: Beaurocratic | O30: Haviamo ricevuto la lettera del S. Mta che molto amorevolmente li scrive, et se bene era Inrisposta d__nra__ antecedente, haviam preso occasion del replicare e scriviamo ancora al Duca di Lerma, che potra' dar la lettera oportunamente e faverirci secondo Il suo solita, e voi potute in quel modo che pare a___ fargli haver l'accluso prego. Quanto alle tele d'oro per Il monast___o della Regina nostra sorella, che sia In cielo, vi si scrisse che Il tempo non poteva esser'bastante per con dur le a fine, ma non si manche __a sollecitarle piu che sia possibile nostro signore vi prosper__ | P30: We have received the letter from His Majesty, who writes to you very kindly, and although it was the previous reply, we have taken the opportunity to reply and we are writing again to the Duke of Lerma, who will be able to deliver the letter in a timely manner and assist us as usual, and you can do as you see fit by having the enclosed request. As for the gold cloth/canvas/fabric for the monastery of our sister Queen, who is in heaven, we wrote that there would not be enough time to complete them, but we will not fail to urge them as much as possible, our lord prospers you.
A31: ID_00030 | B31: ASF, Acquisti e Doni, Fol 242, Ins 3. | D31: 59-60 | E31: 1616/00/00 | F31: Firenze/Fiorenza | G31: von Habsburg, Maria Magdalena | H31: Ruler: Arciduchessa d'Austria e Gran Duchessa di Toscana | I31: d'Elci, Orso | J31: Ambassador: Conte e Ambassadore | K31: Beaurocratic | O31: Per continuar' la cominciata confidenza scriviamo al Re, et al Signore Duca di Lerma, et haviam[o] fatto capital del vostro prudente Avvertimento, mandando la lettera per S. Mta tutta di nostra m~a_ (?), et la Inviamo inclusa nel medesimo Piego del Esso signore Duca, che lo presenterete, accompagnandolo con quelle parole, che piu' vi parranno a preposito in rimostranza di detta confidenza, et del nostre Devotissimo affetto verso la Mta sua; Appresso desideriamo, che havendo Pietro Tacca (or Tava?) scultor del Cavallo, mandato a Donare al Re un Crucifisso di Bronzo, che a' venderlo qua' ne havria potuto cavar' due mila scudi, voi destram__e insinuasse al signore Duca di Lerma Il Primor dell'Artifizio d'esso, et il suo pregio, et poi concludesse, che havendo quest'Artefice di sup proprio moto donato si bell'opera ad un Re tanto potente, che egli ha sperato, che dalla sua Real mano, deva venir ricompensa piu', che equivalen__te et Informatelo ancor'che quest'huomo per la sua virtu' e' molto amato, et prezzato dal serenissimo Gran Duca, et da' me, Accio' che tanto piu volentier' S. Ecc__a habbia a protegerlo, et rappresentar' a' __ M.ta la conven__za del Remunerarlo. Rimettendo il resto alla Dilig[enza] et prudenza vostra; Volendo che haviate per raccomandato ancora Il Proposto di Massa duo frello [fratello], che e Venuto costa a' presentar Il Cavallo, ma avvertiretedi frattar In modo, che si il Re gli fara' alcuna mercede non apparisca fatta a conto nostro. Et Il signore riprosperi. | P31: To continue the confidence we have begun, we write to the King and to the Lord Duke of Lerma, and we have taken advantage of your prudent advice by sending the letter to His Majesty entirely from our mother (?), and we are sending it included in the same envelope from the Lord Duke, which you will present to him, accompanying it with those words which you consider most appropriate in demonstration of the said confidence and of our most devoted affection towards his Mother; We next desire that, since Pietro Tacca (or Tava?), the sculptor of the Horse, has sent a Bronze Crucifix to the King, which he could have sold here for two thousand crowns, you should dexterously insinuate to the Lord Duke of Lerma the origin of its workmanship and its value, and then conclude that since this Artist has of his own accord donated such a beautiful work to such a powerful King, he has hoped that from his Royal hand, a more than equivalent reward will come. and also inform him that this man, for his virtue, is much loved and prized by the Most Serene Grand Duke, and by me, so that His Excellency will be all the more willing to protect him and represent to the Majesty the King the appropriateness of remunerating him. Leaving the rest to your diligence and prudence. I want you to also have recommended the Provost of Massa, his brother, who came here to present the Knight, but you will take care to do so in such a way that if the King gives him any reward, it will not appear to have been done at our expense. And [basically God bless you] | Q31: just thinking here. it's a good thing to have BOTH maria maddalena and christine of lorraine at the medici court because even though those two nations are/have been at odds, they aren't completely at odds all the time. it is good to be allied with both of them when possible and only pick sides when you sort of have to. and anyway, Margaret and Phillip's daughter Anne is the Queen of France, so it's not like they aren't connected by blood just like every other important court
